2019-02-21 22:22:58,654 INFO: Starting data acquisition [in /home/holger/git/serDev/config.py:43]
2019-02-21 22:23:20,952 INFO: Starting data acquisition [in /home/holger/git/serDev/config.py:43]
2019-02-21 22:23:43,503 INFO: Starting data acquisition [in /home/holger/git/serDev/config.py:43]
2019-02-21 22:24:19,230 INFO: Starting data acquisition [in /home/holger/git/serDev/config.py:43]
2019-02-21 22:26:01,115 INFO: Starting data acquisition [in /home/holger/git/serDev/config.py:43]
2019-02-21 22:26:09,937 INFO: Starting data acquisition [in /home/holger/git/serDev/config.py:43]
2019-02-21 22:26:39,396 INFO: Starting data acquisition [in /home/holger/git/serDev/config.py:43]
2019-02-21 22:27:22,187 INFO: Starting data acquisition [in /home/holger/git/serDev/config.py:43]
2019-02-21 22:27:36,784 INFO: Starting data acquisition [in /home/holger/git/serDev/config.py:43]
2019-02-21 22:37:15,646 INFO: Starting data acquisition [in /home/holger/git/serDev/config.py:43]
2019-02-21 22:37:29,990 INFO: Starting data acquisition [in /home/holger/git/serDev/config.py:43]
2019-02-21 22:37:48,761 INFO: Starting data acquisition [in /home/holger/git/serDev/config.py:43]
2019-02-21 22:38:08,074 INFO: Starting data acquisition [in /home/holger/git/serDev/config.py:43]
2019-02-21 22:39:21,887 INFO: Starting data acquisition [in /home/holger/git/serDev/config.py:43]
2019-02-21 22:39:37,820 INFO: Starting data acquisition [in /home/holger/git/serDev/config.py:43]
2019-02-21 22:39:54,973 INFO: Starting data acquisition [in /home/holger/git/serDev/config.py:43]
2019-02-21 22:40:50,692 INFO: Starting data acquisition [in /home/holger/git/serDev/config.py:43]
2019-02-21 22:41:11,492 INFO: Starting data acquisition [in /home/holger/git/serDev/config.py:43]
2019-02-21 22:41:29,673 INFO: Starting data acquisition [in /home/holger/git/serDev/config.py:43]
2019-02-21 22:42:32,876 INFO: Starting data acquisition [in /home/holger/git/serDev/config.py:43]
2019-02-21 22:42:58,871 INFO: Starting data acquisition [in /home/holger/git/serDev/config.py:43]
2019-02-21 22:43:31,970 INFO: Starting data acquisition [in /home/holger/git/serDev/config.py:43]
2019-02-21 22:44:04,628 INFO: Starting data acquisition [in /home/holger/git/serDev/config.py:43]
2019-02-21 22:45:20,401 INFO: Starting data acquisition [in /home/holger/git/serDev/config.py:43]
2019-02-21 22:45:29,793 INFO: Starting data acquisition [in /home/holger/git/serDev/config.py:43]
2019-02-21 22:45:58,404 INFO: Starting data acquisition [in /home/holger/git/serDev/config.py:43]
2019-02-21 22:46:07,056 INFO: Starting data acquisition [in /home/holger/git/serDev/config.py:43]
2019-02-21 22:47:29,055 INFO: Starting data acquisition [in /home/holger/git/serDev/config.py:43]
2019-02-21 22:48:10,418 INFO: Starting data acquisition [in /home/holger/git/serDev/config.py:43]
2019-02-21 22:48:10,451 ERROR: EXCEPTION occured [in /home/holger/git/serDev/devices/ptb330.py:76]
Traceback (most recent call last):
  File "/home/holger/git/serDev/devices/ptb330.py", line 71, in open_connection
    if not self.thread.open_ser_connection(ser):
  File "/home/holger/git/serDev/modules/threads.py", line 61, in open_ser_connection
    raise e from None
  File "/home/holger/git/serDev/modules/threads.py", line 56, in open_ser_connection
    self.sio = io.TextIOWrapper(io.BufferedReader(self.conn, 1),
NameError: name 'io' is not defined
2019-02-21 22:48:57,230 INFO: Starting data acquisition [in /home/holger/git/serDev/config.py:43]
2019-02-21 22:48:57,265 ERROR: EXCEPTION occured [in /home/holger/git/serDev/devices/ptb330.py:77]
Traceback (most recent call last):
  File "/home/holger/git/serDev/devices/ptb330.py", line 72, in open_connection
    if not self.thread.open_ser_connection(ser):
  File "/home/holger/git/serDev/modules/threads.py", line 61, in open_ser_connection
    raise e from None
  File "/home/holger/git/serDev/modules/threads.py", line 56, in open_ser_connection
    self.sio = io.TextIOWrapper(io.BufferedReader(self.conn, 1),
NameError: name 'io' is not defined
2019-02-21 22:49:42,373 INFO: Starting data acquisition [in /home/holger/git/serDev/config.py:43]
2019-02-21 22:49:42,406 ERROR: EXCEPTION occured [in /home/holger/git/serDev/devices/ptb330.py:77]
Traceback (most recent call last):
  File "/home/holger/git/serDev/devices/ptb330.py", line 72, in open_connection
    if not self.thread.open_ser_connection(ser):
  File "/home/holger/git/serDev/modules/threads.py", line 61, in open_ser_connection
    raise e from None
  File "/home/holger/git/serDev/modules/threads.py", line 56, in open_ser_connection
    self.sio = io.TextIOWrapper(io.BufferedReader(self.conn, 1),
NameError: name 'io' is not defined
2019-02-21 22:53:44,444 INFO: Starting data acquisition [in /home/holger/git/serDev/config.py:43]
2019-02-21 22:54:14,790 INFO: Starting data acquisition [in /home/holger/git/serDev/config.py:43]
2019-02-21 22:54:14,822 ERROR: EXCEPTION occured [in /home/holger/git/serDev/devices/ptb330.py:77]
Traceback (most recent call last):
  File "/home/holger/git/serDev/devices/ptb330.py", line 72, in open_connection
    if not self.thread.open_ser_connection(ser):
  File "/home/holger/git/serDev/modules/threads.py", line 61, in open_ser_connection
    raise e from None
  File "/home/holger/git/serDev/modules/threads.py", line 56, in open_ser_connection
    self.sio = io.TextIOWrapper(io.BufferedReader(self.conn, 1),
NameError: name 'io' is not defined
2019-02-21 22:55:17,663 INFO: Starting data acquisition [in /home/holger/git/serDev/config.py:43]
2019-02-21 22:55:17,699 ERROR: Serial Exception [in /home/holger/git/serDev/devices/ptb330.py:75]
Traceback (most recent call last):
  File "/home/holger/git/serDev/devices/ptb330.py", line 72, in open_connection
    if not self.thread.open_ser_connection(ser):
  File "/home/holger/git/serDev/modules/threads.py", line 62, in open_ser_connection
    raise e from None
  File "/home/holger/git/serDev/modules/threads.py", line 56, in open_ser_connection
    self.conn.open()
  File "/usr/local/lib/python3.5/dist-packages/serial/serialposix.py", line 261, in open
    raise SerialException("Port is already open.")
serial.serialutil.SerialException: Port is already open.
2019-02-21 22:57:33,704 INFO: Starting data acquisition [in /home/holger/git/serDev/config.py:43]
2019-02-21 22:57:33,736 ERROR: Serial Exception [in /home/holger/git/serDev/devices/ptb330.py:75]
Traceback (most recent call last):
  File "/home/holger/git/serDev/devices/ptb330.py", line 72, in open_connection
    if not self.thread.open_ser_connection(ser):
  File "/home/holger/git/serDev/modules/threads.py", line 62, in open_ser_connection
    raise e from None
  File "/home/holger/git/serDev/modules/threads.py", line 56, in open_ser_connection
    self.conn.open()
  File "/usr/local/lib/python3.5/dist-packages/serial/serialposix.py", line 261, in open
    raise SerialException("Port is already open.")
serial.serialutil.SerialException: Port is already open.
2019-02-21 22:58:54,566 INFO: Starting data acquisition [in /home/holger/git/serDev/config.py:43]
2019-02-21 22:58:54,599 ERROR: Serial Exception [in /home/holger/git/serDev/devices/ptb330.py:75]
Traceback (most recent call last):
  File "/home/holger/git/serDev/devices/ptb330.py", line 72, in open_connection
    if not self.thread.open_ser_connection(ser):
  File "/home/holger/git/serDev/modules/threads.py", line 62, in open_ser_connection
    raise e from None
  File "/home/holger/git/serDev/modules/threads.py", line 56, in open_ser_connection
    self.conn.open()
  File "/usr/local/lib/python3.5/dist-packages/serial/serialposix.py", line 261, in open
    raise SerialException("Port is already open.")
serial.serialutil.SerialException: Port is already open.
2019-02-21 22:59:23,273 INFO: Starting data acquisition [in /home/holger/git/serDev/config.py:43]
2019-02-21 22:59:23,303 ERROR: Serial Exception [in /home/holger/git/serDev/devices/ptb330.py:75]
Traceback (most recent call last):
  File "/home/holger/git/serDev/devices/ptb330.py", line 72, in open_connection
    if not self.thread.open_ser_connection(ser):
  File "/home/holger/git/serDev/modules/threads.py", line 62, in open_ser_connection
    raise e from None
  File "/home/holger/git/serDev/modules/threads.py", line 56, in open_ser_connection
    self.conn.open()
  File "/usr/local/lib/python3.5/dist-packages/serial/serialposix.py", line 261, in open
    raise SerialException("Port is already open.")
serial.serialutil.SerialException: Port is already open.
2019-02-21 23:00:43,019 INFO: Starting data acquisition [in /home/holger/git/serDev/config.py:43]
2019-02-21 23:00:43,053 ERROR: Serial Exception [in /home/holger/git/serDev/devices/ptb330.py:75]
Traceback (most recent call last):
  File "/home/holger/git/serDev/devices/ptb330.py", line 72, in open_connection
    if not self.thread.open_ser_connection(ser):
  File "/home/holger/git/serDev/modules/threads.py", line 62, in open_ser_connection
    raise e from None
  File "/home/holger/git/serDev/modules/threads.py", line 56, in open_ser_connection
    self.conn.open()
  File "/usr/local/lib/python3.5/dist-packages/serial/serialposix.py", line 261, in open
    raise SerialException("Port is already open.")
serial.serialutil.SerialException: Port is already open.
2019-02-21 23:01:09,432 INFO: Starting data acquisition [in /home/holger/git/serDev/config.py:43]
2019-02-21 23:01:09,466 ERROR: Serial Exception [in /home/holger/git/serDev/devices/ptb330.py:75]
Traceback (most recent call last):
  File "/home/holger/git/serDev/devices/ptb330.py", line 72, in open_connection
    if not self.thread.open_ser_connection(ser):
  File "/home/holger/git/serDev/modules/threads.py", line 62, in open_ser_connection
    raise e from None
  File "/home/holger/git/serDev/modules/threads.py", line 56, in open_ser_connection
    self.conn.open()
  File "/usr/local/lib/python3.5/dist-packages/serial/serialposix.py", line 261, in open
    raise SerialException("Port is already open.")
serial.serialutil.SerialException: Port is already open.
2019-02-21 23:02:00,037 INFO: Starting data acquisition [in /home/holger/git/serDev/config.py:43]
